<robot name = "minmbot">
	<link name = "base_footprint" />
	<link name = "base_link" />
	<link name = "front_left_wheel" />
	<link name = "front_right_wheel" />
	<link name = "back_left_wheel" />	
	<link name = "back_right_wheel" />
	<link name = "lidar" />
	<link name = "gps" />
	<link name = "imu" />

	<!--joint name = "base_footprint_to_base_link_joint" type = "fixed" >
		<parent link="base_footprint"/>
		<child link="base_link"/>
		<origin xyz = "0 0 0.1016" rpy = "0 0 0" />
	</joint-->

	<joint name = "base_link_to_front_left_wheel_joint" type = "continuous" >
		<parent link="base_link"/>
    		<child link="front_left_wheel"/>
		<origin xyz = "0.1305 0.09525 -0.0416" rpy = "0 0 0" />
		<axis xyz = "0 0 1" />
  	</joint>

	<joint name = "base_link_to_front_right_wheel_joint" type = "continuous" >
		<parent link="base_link"/>
    		<child link="front_right_wheel"/>
		<origin xyz = "0.1305 -0.09525 -0.0416" rpy = "0 0 0" />
		<axis xyz = "0 0 1" />
  	</joint>


	<joint name = "base_link_to_back_left_wheel_joint" type = "fixed" >
		<parent link="base_link"/>
    		<child link="back_left_wheel"/>
		<origin xyz = "-0.1305 0.09525 -0.0416" rpy = "0 0 0" />
  	</joint>


	<joint name = "base_link_to_back_right_wheel_joint" type = "fixed" >
		<parent link="base_link"/>
    		<child link="back_right_wheel"/>
		<origin xyz = "-0.1305 -0.09525 -0.0416" rpy = "0 0 0" />
  	</joint>


	<joint name = "base_link_to_lidar_joint" type = "fixed" >
		<parent link="base_link"/>
    		<child link="lidar"/>
		<origin xyz = "0.0254 0 0.1143" rpy = "0 0 0" />
  	</joint>


	<joint name = "base_link_to_gps_joint" type = "fixed" >
		<parent link="base_link"/>
    		<child link = "gps" />
		<origin xyz = "-0.0381 0 0.10795" rpy = "0 0 0" />
  	</joint>

	<joint name = "base_link_to_imu_joint" type = "fixed" >
		<parent link="base_link"/>
    		<child link="imu"/>
		<origin xyz = "-0.1016 0 0.10795" rpy = "0 0 0" />
  	</joint>





</robot>
